<mujoco model="humanoid">
  <compiler coordinate="local"/>
  <default>
    <joint damping="0.0" armature="0.01" stiffness="0.0" limited="true"/>
    <geom conaffinity="1" condim="3" contype="7" margin="0.001" rgba="0.8 0.6 .4 1"/>
  </default>
  <asset>
    <texture type="skybox" builtin="gradient" rgb1=".4 .5 .6" rgb2="0 0 0" width="100" height="100"/>
    <texture builtin="flat" height="1278" mark="cross" markrgb="1 1 1" name="texgeom" random="0.01" rgb1="0.8 0.6 0.4" rgb2="0.8 0.6 0.4" type="cube" width="127"/>
    <texture builtin="checker" height="100" name="texplane" rgb1="0 0 0" rgb2="0.8 0.8 0.8" type="2d" width="100"/>
    <material name="MatPlane" reflectance="0.5" shininess="1" specular="1" texrepeat="60 60" texture="texplane"/>
    <material name="geom" texture="texgeom" texuniform="true"/>
  </asset>
  <worldbody>
    <light cutoff="100" diffuse="1 1 1" dir="-0 0 -1.3" directional="true" exponent="1" pos="0 0 1.3" specular=".1 .1 .1"/>
    <geom conaffinity="1" condim="3" name="floor" pos="0 0 0" rgba="0.8 0.9 0.8 1" size="100 100 .2" type="plane" material="MatPlane"/>
    <body name="Pelvis" pos="0.0033 -0.3775 0.0086">
      <freejoint name="Pelvis"/>
      <geom type="sphere" contype="1" conaffinity="1" density="4629.6296296296305" size="0.1051" pos="0.0000 0.0000 0.0000" name="Pelvis"/>
      <body name="L_Hip" pos="0.0606 -0.0959 -0.0248">
        <joint name="L_Hip_x" type="hinge" pos="0 0 0" axis="1 0 0" user="250 2.5 1 500 10 2" armature="0.01" range="-90.0000 90.0000" damping="0" stiffness="0"/>
        <joint name="L_Hip_y" type="hinge" pos="0 0 0" axis="0 1 0" user="250 2.5 1 500 10 2" armature="0.01" range="-90.0000 90.0000" damping="0" stiffness="0"/>
        <joint name="L_Hip_z" type="hinge" pos="0 0 0" axis="0 0 1" user="250 2.5 1 500 10 2" armature="0.01" range="-90.0000 90.0000" damping="0" stiffness="0"/>
        <geom type="capsule" contype="1" conaffinity="1" density="2040.816327" fromto="0.0124 -0.0757 -0.0009 0.0497 -0.3027 -0.0037" size="0.0626" name="L_Hip"/>
        <body name="L_Knee" pos="0.0622 -0.3784 -0.0047">
          <joint name="L_Knee_x" type="hinge" pos="0 0 0" axis="1 0 0" user="250 2.5 1 500 10 2" armature="0.01" range="-180.0000 180.0000" damping="0" stiffness="0"/>
          <joint name="L_Knee_y" type="hinge" pos="0 0 0" axis="0 1 0" user="250 2.5 1 500 10 2" armature="0.01" range="-5.6250 5.6250" damping="0" stiffness="0"/>
          <joint name="L_Knee_z" type="hinge" pos="0 0 0" axis="0 0 1" user="250 2.5 1 500 10 2" armature="0.01" range="-5.6250 5.6250" damping="0" stiffness="0"/>
          <geom type="capsule" contype="1" conaffinity="1" density="1234.567901" fromto="-0.0087 -0.0818 -0.0066 -0.0349 -0.3273 -0.0264" size="0.0548" name="L_Knee"/>
          <body name="L_Ankle" pos="-0.0436 -0.4091 -0.033">
            <joint name="L_Ankle_x" type="hinge" pos="0 0 0" axis="1 0 0" user="150 2.5 1 500 10 2" armature="0.01" range="-90.0000 90.0000" damping="0" stiffness="0"/>
            <joint name="L_Ankle_y" type="hinge" pos="0 0 0" axis="0 1 0" user="150 2.5 1 500 10 2" armature="0.01" range="-90.0000 90.0000" damping="0" stiffness="0"/>
            <joint name="L_Ankle_z" type="hinge" pos="0 0 0" axis="0 0 1" user="150 2.5 1 500 10 2" armature="0.01" range="-90.0000 90.0000" damping="0" stiffness="0"/>
            <geom type="box" density="448.034257" pos="0.0427 -0.0298 0.0231" size="0.0515 0.0479 0.0868" quat="1.0000 0.0000 0.0000 0.0000" name="L_Ankle"/>
            <body name="L_Toe" pos="0.0496 -0.0597 0.1193">
              <joint name="L_Toe_x" type="hinge" pos="0 0 0" axis="1 0 0" user="150 1 1 500 1 1" armature="0.01" range="-90.0000 90.0000" damping="0" stiffness="0"/>
              <joint name="L_Toe_y" type="hinge" pos="0 0 0" axis="0 1 0" user="150 1 1 500 1 1" armature="0.01" range="-45.0000 45.0000" damping="0" stiffness="0"/>
              <joint name="L_Toe_z" type="hinge" pos="0 0 0" axis="0 0 1" user="150 1 1 500 1 1" armature="0.01" range="-45.0000 45.0000" damping="0" stiffness="0"/>
              <geom type="box" density="419.319439" pos="-0.0069 0.0032 0.0259" size="0.0493 0.0211 0.0505" quat="1.0000 0.0000 0.0000 0.0000" name="L_Toe"/>
            </body>
          </body>
        </body>
      </body>
      <body name="R_Hip" pos="-0.0658 -0.1076 -0.0193">
        <joint name="R_Hip_x" type="hinge" pos="0 0 0" axis="1 0 0" user="250 2.5 1 500 10 2" armature="0.01" range="-90.0000 90.0000" damping="0" stiffness="0"/>
        <joint name="R_Hip_y" type="hinge" pos="0 0 0" axis="0 1 0" user="250 2.5 1 500 10 2" armature="0.01" range="-90.0000 90.0000" damping="0" stiffness="0"/>
        <joint name="R_Hip_z" type="hinge" pos="0 0 0" axis="0 0 1" user="250 2.5 1 500 10 2" armature="0.01" range="-90.0000 90.0000" damping="0" stiffness="0"/>
        <geom type="capsule" contype="1" conaffinity="1" density="2040.816327" fromto="-0.0103 -0.0723 -0.0026 -0.0411 -0.2893 -0.0104" size="0.062" name="R_Hip"/>
        <body name="R_Knee" pos="-0.0514 -0.3616 -0.013">
          <joint name="R_Knee_x" type="hinge" pos="0 0 0" axis="1 0 0" user="250 2.5 1 500 10 2" armature="0.01" range="-180.0000 180.0000" damping="0" stiffness="0"/>
          <joint name="R_Knee_y" type="hinge" pos="0 0 0" axis="0 1 0" user="250 2.5 1 500 10 2" armature="0.01" range="-5.6250 5.6250" damping="0" stiffness="0"/>
          <joint name="R_Knee_z" type="hinge" pos="0 0 0" axis="0 0 1" user="250 2.5 1 500 10 2" armature="0.01" range="-5.6250 5.6250" damping="0" stiffness="0"/>
          <geom type="capsule" contype="1" conaffinity="1" density="1234.567901" fromto="0.0028 -0.0834 -0.0042 0.0113 -0.3335 -0.0167" size="0.0564" name="R_Knee"/>
          <body name="R_Ankle" pos="0.0141 -0.4169 -0.0209">
            <joint name="R_Ankle_x" type="hinge" pos="0 0 0" axis="1 0 0" user="150 1 1 500 10 2" armature="0.01" range="-90.0000 90.0000" damping="0" stiffness="0"/>
            <joint name="R_Ankle_y" type="hinge" pos="0 0 0" axis="0 1 0" user="150 1 1 500 10 2" armature="0.01" range="-90.0000 90.0000" damping="0" stiffness="0"/>
            <joint name="R_Ankle_z" type="hinge" pos="0 0 0" axis="0 0 1" user="150 1 1 500 10 2" armature="0.01" range="-90.0000 90.0000" damping="0" stiffness="0"/>
            <geom type="box" density="448.028655" pos="-0.0255 -0.0273 0.0139" size="0.0515 0.0479 0.0868" quat="1.0000 0.0000 0.0000 0.0000" name="R_Ankle"/>
            <body name="R_Toe" pos="-0.0406 -0.0598 0.1202">
              <joint name="R_Toe_x" type="hinge" pos="0 0 0" axis="1 0 0" user="150 1 1 500 1 1" armature="0.01" range="-90.0000 90.0000" damping="0" stiffness="0"/>
              <joint name="R_Toe_y" type="hinge" pos="0 0 0" axis="0 1 0" user="150 1 1 500 1 1" armature="0.01" range="-45.0000 45.0000" damping="0" stiffness="0"/>
              <joint name="R_Toe_z" type="hinge" pos="0 0 0" axis="0 0 1" user="150 1 1 500 1 1" armature="0.01" range="-45.0000 45.0000" damping="0" stiffness="0"/>
              <geom type="box" density="419.318876" pos="0.0151 0.0058 0.0158" size="0.0493 0.0211 0.0505" quat="1.0000 0.0000 0.0000 0.0000" name="R_Toe"/>
            </body>
          </body>
        </body>
      </body>
      <body name="Torso" pos="-0.0033 0.1151 -0.0315">
        <joint name="Torso_x" type="hinge" pos="0 0 0" axis="1 0 0" user="500 5 1 500 10 2" armature="0.01" range="-60.0000 60.0000" damping="0" stiffness="0"/>
        <joint name="Torso_y" type="hinge" pos="0 0 0" axis="0 1 0" user="500 5 1 500 10 2" armature="0.01" range="-60.0000 60.0000" damping="0" stiffness="0"/>
        <joint name="Torso_z" type="hinge" pos="0 0 0" axis="0 0 1" user="500 5 1 500 10 2" armature="0.01" range="-60.0000 60.0000" damping="0" stiffness="0"/>
        <geom type="capsule" contype="1" conaffinity="1" density="2040.816327" fromto="0.0051 0.0628 -0.0028 0.0062 0.0767 -0.0034" size="0.0792" name="Torso"/>
        <body name="Spine" pos="0.0112 0.1395 -0.0062">
          <joint name="Spine_x" type="hinge" pos="0 0 0" axis="1 0 0" user="500 5 1 500 10 2" armature="0.01" range="-60.0000 60.0000" damping="0" stiffness="0"/>
          <joint name="Spine_y" type="hinge" pos="0 0 0" axis="0 1 0" user="500 5 1 500 10 2" armature="0.01" range="-60.0000 60.0000" damping="0" stiffness="0"/>
          <joint name="Spine_z" type="hinge" pos="0 0 0" axis="0 0 1" user="500 5 1 500 10 2" armature="0.01" range="-60.0000 60.0000" damping="0" stiffness="0"/>
          <geom type="capsule" contype="1" conaffinity="1" density="2040.816327" fromto="-0.0055 0.0250 0.0143 -0.0067 0.0306 0.0175" size="0.0816" name="Spine"/>
          <body name="Chest" pos="-0.0122 0.0555 0.0318">
            <joint name="Chest_x" type="hinge" pos="0 0 0" axis="1 0 0" user="500 5 1 500 10 2" armature="0.01" range="-60.0000 60.0000" damping="0" stiffness="0"/>
            <joint name="Chest_y" type="hinge" pos="0 0 0" axis="0 1 0" user="500 5 1 500 10 2" armature="0.01" range="-60.0000 60.0000" damping="0" stiffness="0"/>
            <joint name="Chest_z" type="hinge" pos="0 0 0" axis="0 0 1" user="500 5 1 500 10 2" armature="0.01" range="-60.0000 60.0000" damping="0" stiffness="0"/>
            <geom type="capsule" contype="1" conaffinity="1" density="2040.816327" fromto="-0.0023 0.0531 -0.0087 -0.0028 0.0649 -0.0106" size="0.1077" name="Chest"/>
            <body name="Neck" pos="-0.013 0.1755 -0.0343">
              <joint name="Neck_x" type="hinge" pos="0 0 0" axis="1 0 0" user="150 1 1 250 50 4" armature="0.01" range="-180.0000 180.0000" damping="0" stiffness="0"/>
              <joint name="Neck_y" type="hinge" pos="0 0 0" axis="0 1 0" user="150 1 1 250 50 4" armature="0.01" range="-180.0000 180.0000" damping="0" stiffness="0"/>
              <joint name="Neck_z" type="hinge" pos="0 0 0" axis="0 0 1" user="150 1 1 250 50 4" armature="0.01" range="-180.0000 180.0000" damping="0" stiffness="0"/>
              <geom type="capsule" contype="1" conaffinity="1" density="1000" fromto="0.0052 0.0343 0.0057 0.0207 0.1373 0.0229" size="0.0449" name="Neck"/>
              <body name="Head" pos="0.0259 0.1717 0.0287">
                <joint name="Head_x" type="hinge" pos="0 0 0" axis="1 0 0" user="150 1 1 250 50 4" armature="0.01" range="-90.0000 90.0000" damping="0" stiffness="0"/>
                <joint name="Head_y" type="hinge" pos="0 0 0" axis="0 1 0" user="150 1 1 250 50 4" armature="0.01" range="-90.0000 90.0000" damping="0" stiffness="0"/>
                <joint name="Head_z" type="hinge" pos="0 0 0" axis="0 0 1" user="150 1 1 250 50 4" armature="0.01" range="-90.0000 90.0000" damping="0" stiffness="0"/>
                <geom type="sphere" contype="1" conaffinity="1" density="1000" size="0.1070" pos="0.0000 0.0000 0.0000" name="Head"/>
              </body>
            </body>
            <body name="L_Thorax" pos="0.0461 0.0896 -0.0085">
              <joint name="L_Thorax_x" type="hinge" pos="0 0 0" axis="1 0 0" user="200 2 1 500 50 4" armature="0.01" range="-180.0000 180.0000" damping="0" stiffness="0"/>
              <joint name="L_Thorax_y" type="hinge" pos="0 0 0" axis="0 1 0" user="200 2 1 500 50 4" armature="0.01" range="-180.0000 180.0000" damping="0" stiffness="0"/>
              <joint name="L_Thorax_z" type="hinge" pos="0 0 0" axis="0 0 1" user="200 2 1 500 50 4" armature="0.01" range="-180.0000 180.0000" damping="0" stiffness="0"/>
              <geom type="capsule" contype="1" conaffinity="1" density="1000" fromto="0.0232 0.0118 -0.0039 0.0927 0.0472 -0.0154" size="0.0498" name="L_Thorax"/>
              <body name="L_Shoulder" pos="0.1159 0.0589 -0.0193">
                <joint name="L_Shoulder_x" type="hinge" pos="0 0 0" axis="1 0 0" user="200 2 1 500 50 4" armature="0.01" range="-180.0000 180.0000" damping="0" stiffness="0"/>
                <joint name="L_Shoulder_y" type="hinge" pos="0 0 0" axis="0 1 0" user="200 2 1 500 50 4" armature="0.01" range="-180.0000 180.0000" damping="0" stiffness="0"/>
                <joint name="L_Shoulder_z" type="hinge" pos="0 0 0" axis="0 0 1" user="200 2 1 500 50 4" armature="0.01" range="-180.0000 180.0000" damping="0" stiffness="0"/>
                <geom type="capsule" contype="1" conaffinity="1" density="1000" fromto="0.0495 -0.0146 -0.0088 0.1981 -0.0583 -0.0351" size="0.0537" name="L_Shoulder"/>
                <body name="L_Elbow" pos="0.2476 -0.0729 -0.0439">
                  <joint name="L_Elbow_x" type="hinge" pos="0 0 0" axis="1 0 0" user="150 1 1 150 10 2" armature="0.01" range="-720.0000 720.0000" damping="0" stiffness="0"/>
                  <joint name="L_Elbow_y" type="hinge" pos="0 0 0" axis="0 1 0" user="150 1 1 150 10 2" armature="0.01" range="-720.0000 720.0000" damping="0" stiffness="0"/>
                  <joint name="L_Elbow_z" type="hinge" pos="0 0 0" axis="0 0 1" user="150 1 1 150 10 2" armature="0.01" range="-720.0000 720.0000" damping="0" stiffness="0"/>
                  <geom type="capsule" contype="1" conaffinity="1" density="1000" fromto="0.0503 0.0051 -0.0003 0.2012 0.0203 -0.0012" size="0.0418" name="L_Elbow"/>
                  <body name="L_Wrist" pos="0.2515 0.0253 -0.0015">
                    <joint name="L_Wrist_x" type="hinge" pos="0 0 0" axis="1 0 0" user="100 1 1 150 1 1" armature="0.01" range="-180.0000 180.0000" damping="0" stiffness="0"/>
                    <joint name="L_Wrist_y" type="hinge" pos="0 0 0" axis="0 1 0" user="100 1 1 150 1 1" armature="0.01" range="-180.0000 180.0000" damping="0" stiffness="0"/>
                    <joint name="L_Wrist_z" type="hinge" pos="0 0 0" axis="0 0 1" user="100 1 1 150 1 1" armature="0.01" range="-180.0000 180.0000" damping="0" stiffness="0"/>
                    <geom type="box" density="1209.684001" pos="0.0531 -0.0011 -0.0032" size="0.0492 0.0128 0.0469" quat="1.0000 0.0000 0.0000 0.0000" name="L_Wrist"/>
                    <body name="L_Index1" pos="0.1035 -0.0084 0.0198">
                      <joint name="L_Index1_x" type="hinge" pos="0 0 0" axis="1 0 0" user="100 10 1 150" armature="0.01" range="-180.0000 180.0000" damping="0" stiffness="0"/>
                      <joint name="L_Index1_y" type="hinge" pos="0 0 0" axis="0 1 0" user="100 10 1 150" armature="0.01" range="-180.0000 180.0000" damping="0" stiffness="0"/>
                      <joint name="L_Index1_z" type="hinge" pos="0 0 0" axis="0 0 1" user="100 10 1 150" armature="0.01" range="-180.0000 180.0000" damping="0" stiffness="0"/>
                      <geom type="capsule" contype="1" conaffinity="1" density="1000" fromto="0.0064 0.0005 0.0006 0.0258 0.0019 0.0023" size="0.0094" name="L_Index1"/>
                      <body name="L_Index2" pos="0.0322 0.0024 0.0029">
                        <joint name="L_Index2_x" type="hinge" pos="0 0 0" axis="1 0 0" user="100 10 1 150" armature="0.01" range="-180.0000 180.0000" damping="0" stiffness="0"/>
                        <joint name="L_Index2_y" type="hinge" pos="0 0 0" axis="0 1 0" user="100 10 1 150" armature="0.01" range="-180.0000 180.0000" damping="0" stiffness="0"/>
                        <joint name="L_Index2_z" type="hinge" pos="0 0 0" axis="0 0 1" user="100 10 1 150" armature="0.01" range="-180.0000 180.0000" damping="0" stiffness="0"/>
                        <geom type="capsule" contype="1" conaffinity="1" density="1000" fromto="0.0045 -0.0005 -0.0000 0.0181 -0.0020 -0.0001" size="0.0078" name="L_Index2"/>
                        <body name="L_Index3" pos="0.0226 -0.0025 -0.0001">
                          <joint name="L_Index3_x" type="hinge" pos="0 0 0" axis="1 0 0" user="100 10 1 150" armature="0.01" range="-180.0000 180.0000" damping="0" stiffness="0"/>
                          <joint name="L_Index3_y" type="hinge" pos="0 0 0" axis="0 1 0" user="100 10 1 150" armature="0.01" range="-180.0000 180.0000" damping="0" stiffness="0"/>
                          <joint name="L_Index3_z" type="hinge" pos="0 0 0" axis="0 0 1" user="100 10 1 150" armature="0.01" range="-180.0000 180.0000" damping="0" stiffness="0"/>
                          <geom type="capsule" contype="1" conaffinity="1" density="1000" fromto="0.0049 -0.0001 0.0004 0.0197 -0.0004 0.0015" size="0.0065" name="L_Index3"/>
                        </body>
                      </body>
                    </body>
                    <body name="L_Middle1" pos="0.1112 -0.006 -0.0041">
                      <joint name="L_Middle1_x" type="hinge" pos="0 0 0" axis="1 0 0" user="100 10 1 150" armature="0.01" range="-180.0000 180.0000" damping="0" stiffness="0"/>
                      <joint name="L_Middle1_y" type="hinge" pos="0 0 0" axis="0 1 0" user="100 10 1 150" armature="0.01" range="-180.0000 180.0000" damping="0" stiffness="0"/>
                      <joint name="L_Middle1_z" type="hinge" pos="0 0 0" axis="0 0 1" user="100 10 1 150" armature="0.01" range="-180.0000 180.0000" damping="0" stiffness="0"/>
                      <geom type="capsule" contype="1" conaffinity="1" density="1000" fromto="0.0062 0.0002 -0.0008 0.0247 0.0007 -0.0033" size="0.0097" name="L_Middle1"/>
                      <body name="L_Middle2" pos="0.0309 0.0008 -0.0041">
                        <joint name="L_Middle2_x" type="hinge" pos="0 0 0" axis="1 0 0" user="100 10 1 150" armature="0.01" range="-180.0000 180.0000" damping="0" stiffness="0"/>
                        <joint name="L_Middle2_y" type="hinge" pos="0 0 0" axis="0 1 0" user="100 10 1 150" armature="0.01" range="-180.0000 180.0000" damping="0" stiffness="0"/>
                        <joint name="L_Middle2_z" type="hinge" pos="0 0 0" axis="0 0 1" user="100 10 1 150" armature="0.01" range="-180.0000 180.0000" damping="0" stiffness="0"/>
                        <geom type="capsule" contype="1" conaffinity="1" density="1000" fromto="0.0047 -0.0004 -0.0008 0.0189 -0.0016 -0.0034" size="0.0072" name="L_Middle2"/>
                        <body name="L_Middle3" pos="0.0237 -0.0021 -0.0042">
                          <joint name="L_Middle3_x" type="hinge" pos="0 0 0" axis="1 0 0" user="100 10 1 150" armature="0.01" range="-180.0000 180.0000" damping="0" stiffness="0"/>
                          <joint name="L_Middle3_y" type="hinge" pos="0 0 0" axis="0 1 0" user="100 10 1 150" armature="0.01" range="-180.0000 180.0000" damping="0" stiffness="0"/>
                          <joint name="L_Middle3_z" type="hinge" pos="0 0 0" axis="0 0 1" user="100 10 1 150" armature="0.01" range="-180.0000 180.0000" damping="0" stiffness="0"/>
                          <geom type="capsule" contype="1" conaffinity="1" density="1000" fromto="0.0051 -0.0000 -0.0004 0.0205 -0.0000 -0.0018" size="0.0062" name="L_Middle3"/>
                        </body>
                      </body>
                    </body>
                    <body name="L_Pinky1" pos="0.0856 -0.0146 -0.0447">
                      <joint name="L_Pinky1_x" type="hinge" pos="0 0 0" axis="1 0 0" user="100 10 1 150" armature="0.01" range="-180.0000 180.0000" damping="0" stiffness="0"/>
                      <joint name="L_Pinky1_y" type="hinge" pos="0 0 0" axis="0 1 0" user="100 10 1 150" armature="0.01" range="-180.0000 180.0000" damping="0" stiffness="0"/>
                      <joint name="L_Pinky1_z" type="hinge" pos="0 0 0" axis="0 0 1" user="100 10 1 150" armature="0.01" range="-180.0000 180.0000" damping="0" stiffness="0"/>
                      <geom type="capsule" contype="1" conaffinity="1" density="1000" fromto="0.0032 -0.0002 -0.0024 0.0127 -0.0010 -0.0096" size="0.0069" name="L_Pinky1"/>
                      <body name="L_Pinky2" pos="0.0159 -0.0012 -0.012">
                        <joint name="L_Pinky2_x" type="hinge" pos="0 0 0" axis="1 0 0" user="100 10 1 150" armature="0.01" range="-180.0000 180.0000" damping="0" stiffness="0"/>
                        <joint name="L_Pinky2_y" type="hinge" pos="0 0 0" axis="0 1 0" user="100 10 1 150" armature="0.01" range="-180.0000 180.0000" damping="0" stiffness="0"/>
                        <joint name="L_Pinky2_z" type="hinge" pos="0 0 0" axis="0 0 1" user="100 10 1 150" armature="0.01" range="-180.0000 180.0000" damping="0" stiffness="0"/>
                        <geom type="capsule" contype="1" conaffinity="1" density="1000" fromto="0.0032 -0.0004 -0.0022 0.0126 -0.0014 -0.0089" size="0.0067" name="L_Pinky2"/>
                        <body name="L_Pinky3" pos="0.0158 -0.0018 -0.0112">
                          <joint name="L_Pinky3_x" type="hinge" pos="0 0 0" axis="1 0 0" user="100 10 1 150" armature="0.01" range="-180.0000 180.0000" damping="0" stiffness="0"/>
                          <joint name="L_Pinky3_y" type="hinge" pos="0 0 0" axis="0 1 0" user="100 10 1 150" armature="0.01" range="-180.0000 180.0000" damping="0" stiffness="0"/>
                          <joint name="L_Pinky3_z" type="hinge" pos="0 0 0" axis="0 0 1" user="100 10 1 150" armature="0.01" range="-180.0000 180.0000" damping="0" stiffness="0"/>
                          <geom type="capsule" contype="1" conaffinity="1" density="1000" fromto="0.0036 0.0000 -0.0018 0.0142 0.0002 -0.0073" size="0.005" name="L_Pinky3"/>
                        </body>
                      </body>
                    </body>
                    <body name="L_Ring1" pos="0.0992 -0.0091 -0.028">
                      <joint name="L_Ring1_x" type="hinge" pos="0 0 0" axis="1 0 0" user="100 10 1 150" armature="0.01" range="-180.0000 180.0000" damping="0" stiffness="0"/>
                      <joint name="L_Ring1_y" type="hinge" pos="0 0 0" axis="0 1 0" user="100 10 1 150" armature="0.01" range="-180.0000 180.0000" damping="0" stiffness="0"/>
                      <joint name="L_Ring1_z" type="hinge" pos="0 0 0" axis="0 0 1" user="100 10 1 150" armature="0.01" range="-180.0000 180.0000" damping="0" stiffness="0"/>
                      <geom type="capsule" contype="1" conaffinity="1" density="1000" fromto="0.0057 0.0003 -0.0011 0.0228 0.0012 -0.0042" size="0.0082" name="L_Ring1"/>
                      <body name="L_Ring2" pos="0.0285 0.0015 -0.0053">
                        <joint name="L_Ring2_x" type="hinge" pos="0 0 0" axis="1 0 0" user="100 10 1 150" armature="0.01" range="-180.0000 180.0000" damping="0" stiffness="0"/>
                        <joint name="L_Ring2_y" type="hinge" pos="0 0 0" axis="0 1 0" user="100 10 1 150" armature="0.01" range="-180.0000 180.0000" damping="0" stiffness="0"/>
                        <joint name="L_Ring2_z" type="hinge" pos="0 0 0" axis="0 0 1" user="100 10 1 150" armature="0.01" range="-180.0000 180.0000" damping="0" stiffness="0"/>
                        <geom type="capsule" contype="1" conaffinity="1" density="1000" fromto="0.0046 -0.0003 -0.0014 0.0185 -0.0012 -0.0058" size="0.0076" name="L_Ring2"/>
                        <body name="L_Ring3" pos="0.0231 -0.0016 -0.0072">
                          <joint name="L_Ring3_x" type="hinge" pos="0 0 0" axis="1 0 0" user="100 10 1 150" armature="0.01" range="-180.0000 180.0000" damping="0" stiffness="0"/>
                          <joint name="L_Ring3_y" type="hinge" pos="0 0 0" axis="0 1 0" user="100 10 1 150" armature="0.01" range="-180.0000 180.0000" damping="0" stiffness="0"/>
                          <joint name="L_Ring3_z" type="hinge" pos="0 0 0" axis="0 0 1" user="100 10 1 150" armature="0.01" range="-180.0000 180.0000" damping="0" stiffness="0"/>
                          <geom type="capsule" contype="1" conaffinity="1" density="1000" fromto="0.0050 0.0001 -0.0010 0.0201 0.0004 -0.0042" size="0.0059" name="L_Ring3"/>
                        </body>
                      </body>
                    </body>
                    <body name="L_Thumb1" pos="0.0411 -0.0187 0.0264">
                      <joint name="L_Thumb1_x" type="hinge" pos="0 0 0" axis="1 0 0" user="100 10 1 150" armature="0.01" range="-180.0000 180.0000" damping="0" stiffness="0"/>
                      <joint name="L_Thumb1_y" type="hinge" pos="0 0 0" axis="0 1 0" user="100 10 1 150" armature="0.01" range="-180.0000 180.0000" damping="0" stiffness="0"/>
                      <joint name="L_Thumb1_z" type="hinge" pos="0 0 0" axis="0 0 1" user="100 10 1 150" armature="0.01" range="-180.0000 180.0000" damping="0" stiffness="0"/>
                      <geom type="capsule" contype="1" conaffinity="1" density="1000" fromto="0.0034 0.0003 0.0050 0.0138 0.0010 0.0202" size="0.0125" name="L_Thumb1"/>
                      <body name="L_Thumb2" pos="0.0172 0.0013 0.0252">
                        <joint name="L_Thumb2_x" type="hinge" pos="0 0 0" axis="1 0 0" user="100 10 1 150" armature="0.01" range="-180.0000 180.0000" damping="0" stiffness="0"/>
                        <joint name="L_Thumb2_y" type="hinge" pos="0 0 0" axis="0 1 0" user="100 10 1 150" armature="0.01" range="-180.0000 180.0000" damping="0" stiffness="0"/>
                        <joint name="L_Thumb2_z" type="hinge" pos="0 0 0" axis="0 0 1" user="100 10 1 150" armature="0.01" range="-180.0000 180.0000" damping="0" stiffness="0"/>
                        <geom type="capsule" contype="1" conaffinity="1" density="1000" fromto="0.0042 -0.0010 0.0031 0.0167 -0.0042 0.0123" size="0.0098" name="L_Thumb2"/>
                        <body name="L_Thumb3" pos="0.0209 -0.0052 0.0154">
                          <joint name="L_Thumb3_x" type="hinge" pos="0 0 0" axis="1 0 0" user="100 10 1 150" armature="0.01" range="-180.0000 180.0000" damping="0" stiffness="0"/>
                          <joint name="L_Thumb3_y" type="hinge" pos="0 0 0" axis="0 1 0" user="100 10 1 150" armature="0.01" range="-180.0000 180.0000" damping="0" stiffness="0"/>
                          <joint name="L_Thumb3_z" type="hinge" pos="0 0 0" axis="0 0 1" user="100 10 1 150" armature="0.01" range="-180.0000 180.0000" damping="0" stiffness="0"/>
                          <geom type="capsule" contype="1" conaffinity="1" density="1000" fromto="0.0046 -0.0006 0.0035 0.0183 -0.0026 0.0139" size="0.0089" name="L_Thumb3"/>
                        </body>
                      </body>
                    </body>
                  </body>
                </body>
              </body>
            </body>
            <body name="R_Thorax" pos="-0.0487 0.0889 -0.015">
              <joint name="R_Thorax_x" type="hinge" pos="0 0 0" axis="1 0 0" user="200 2 1 150 10 2" armature="0.01" range="-180.0000 180.0000" damping="0" stiffness="0"/>
              <joint name="R_Thorax_y" type="hinge" pos="0 0 0" axis="0 1 0" user="200 2 1 150 10 2" armature="0.01" range="-180.0000 180.0000" damping="0" stiffness="0"/>
              <joint name="R_Thorax_z" type="hinge" pos="0 0 0" axis="0 0 1" user="200 2 1 150 10 2" armature="0.01" range="-180.0000 180.0000" damping="0" stiffness="0"/>
              <geom type="capsule" contype="1" conaffinity="1" density="1000" fromto="-0.0200 0.0108 -0.0033 -0.0799 0.0434 -0.0130" size="0.0548" name="R_Thorax"/>
              <body name="R_Shoulder" pos="-0.0998 0.0542 -0.0163">
                <joint name="R_Shoulder_x" type="hinge" pos="0 0 0" axis="1 0 0" user="200 2 1 250 10 2" armature="0.01" range="-180.0000 180.0000" damping="0" stiffness="0"/>
                <joint name="R_Shoulder_y" type="hinge" pos="0 0 0" axis="0 1 0" user="200 2 1 250 10 2" armature="0.01" range="-180.0000 180.0000" damping="0" stiffness="0"/>
                <joint name="R_Shoulder_z" type="hinge" pos="0 0 0" axis="0 0 1" user="200 2 1 250 10 2" armature="0.01" range="-180.0000 180.0000" damping="0" stiffness="0"/>
                <geom type="capsule" contype="1" conaffinity="1" density="1000" fromto="-0.0528 -0.0070 -0.0055 -0.2110 -0.0282 -0.0218" size="0.0537" name="R_Shoulder"/>
                <body name="R_Elbow" pos="-0.2638 -0.0352 -0.0273">
                  <joint name="R_Elbow_x" type="hinge" pos="0 0 0" axis="1 0 0" user="150 1 1 150 10 2" armature="0.01" range="-720.0000 720.0000" damping="0" stiffness="0"/>
                  <joint name="R_Elbow_y" type="hinge" pos="0 0 0" axis="0 1 0" user="150 1 1 150 10 2" armature="0.01" range="-720.0000 720.0000" damping="0" stiffness="0"/>
                  <joint name="R_Elbow_z" type="hinge" pos="0 0 0" axis="0 0 1" user="150 1 1 150 10 2" armature="0.01" range="-720.0000 720.0000" damping="0" stiffness="0"/>
                  <geom type="capsule" contype="1" conaffinity="1" density="1000" fromto="-0.0498 -0.0007 -0.0029 -0.1992 -0.0030 -0.0116" size="0.0421" name="R_Elbow"/>
                  <body name="R_Wrist" pos="-0.249 -0.0037 -0.0145">
                    <joint name="R_Wrist_x" type="hinge" pos="0 0 0" axis="1 0 0" user="100 1 1 150 1 1" armature="0.01" range="-180.0000 180.0000" damping="0" stiffness="0"/>
                    <joint name="R_Wrist_y" type="hinge" pos="0 0 0" axis="0 1 0" user="100 1 1 150 1 1" armature="0.01" range="-180.0000 180.0000" damping="0" stiffness="0"/>
                    <joint name="R_Wrist_z" type="hinge" pos="0 0 0" axis="0 0 1" user="100 1 1 150 1 1" armature="0.01" range="-180.0000 180.0000" damping="0" stiffness="0"/>
                    <geom type="box" density="1241.551579" pos="-0.0546 -0.0044 -0.0032" size="0.0463 0.0128 0.0469" quat="1.0000 0.0000 0.0000 0.0000" name="R_Wrist"/>
                    <body name="R_Index1" pos="-0.1015 -0.0117 0.0197">
                      <joint name="R_Index1_x" type="hinge" pos="0 0 0" axis="1 0 0" user="100 10 1 150" armature="0.01" range="-180.0000 180.0000" damping="0" stiffness="0"/>
                      <joint name="R_Index1_y" type="hinge" pos="0 0 0" axis="0 1 0" user="100 10 1 150" armature="0.01" range="-180.0000 180.0000" damping="0" stiffness="0"/>
                      <joint name="R_Index1_z" type="hinge" pos="0 0 0" axis="0 0 1" user="100 10 1 150" armature="0.01" range="-180.0000 180.0000" damping="0" stiffness="0"/>
                      <geom type="capsule" contype="1" conaffinity="1" density="1000" fromto="-0.0064 0.0005 0.0006 -0.0258 0.0019 0.0023" size="0.0094" name="R_Index1"/>
                      <body name="R_Index2" pos="-0.0322 0.0024 0.0029">
                        <joint name="R_Index2_x" type="hinge" pos="0 0 0" axis="1 0 0" user="100 10 1 150" armature="0.01" range="-180.0000 180.0000" damping="0" stiffness="0"/>
                        <joint name="R_Index2_y" type="hinge" pos="0 0 0" axis="0 1 0" user="100 10 1 150" armature="0.01" range="-180.0000 180.0000" damping="0" stiffness="0"/>
                        <joint name="R_Index2_z" type="hinge" pos="0 0 0" axis="0 0 1" user="100 10 1 150" armature="0.01" range="-180.0000 180.0000" damping="0" stiffness="0"/>
                        <geom type="capsule" contype="1" conaffinity="1" density="1000" fromto="-0.0045 -0.0005 -0.0000 -0.0181 -0.0020 -0.0001" size="0.0078" name="R_Index2"/>
                        <body name="R_Index3" pos="-0.0226 -0.0025 -0.0001">
                          <joint name="R_Index3_x" type="hinge" pos="0 0 0" axis="1 0 0" user="100 10 1 150" armature="0.01" range="-180.0000 180.0000" damping="0" stiffness="0"/>
                          <joint name="R_Index3_y" type="hinge" pos="0 0 0" axis="0 1 0" user="100 10 1 150" armature="0.01" range="-180.0000 180.0000" damping="0" stiffness="0"/>
                          <joint name="R_Index3_z" type="hinge" pos="0 0 0" axis="0 0 1" user="100 10 1 150" armature="0.01" range="-180.0000 180.0000" damping="0" stiffness="0"/>
                          <geom type="capsule" contype="1" conaffinity="1" density="1000" fromto="-0.0041 -0.0001 0.0004 -0.0165 -0.0004 0.0015" size="0.0068" name="R_Index3"/>
                        </body>
                      </body>
                    </body>
                    <body name="R_Middle1" pos="-0.1092 -0.0093 -0.0041">
                      <joint name="R_Middle1_x" type="hinge" pos="0 0 0" axis="1 0 0" user="100 10 1 150" armature="0.01" range="-180.0000 180.0000" damping="0" stiffness="0"/>
                      <joint name="R_Middle1_y" type="hinge" pos="0 0 0" axis="0 1 0" user="100 10 1 150" armature="0.01" range="-180.0000 180.0000" damping="0" stiffness="0"/>
                      <joint name="R_Middle1_z" type="hinge" pos="0 0 0" axis="0 0 1" user="100 10 1 150" armature="0.01" range="-180.0000 180.0000" damping="0" stiffness="0"/>
                      <geom type="capsule" contype="1" conaffinity="1" density="1000" fromto="-0.0062 0.0002 -0.0008 -0.0247 0.0007 -0.0033" size="0.0097" name="R_Middle1"/>
                      <body name="R_Middle2" pos="-0.0309 0.0008 -0.0041">
                        <joint name="R_Middle2_x" type="hinge" pos="0 0 0" axis="1 0 0" user="100 10 1 150" armature="0.01" range="-180.0000 180.0000" damping="0" stiffness="0"/>
                        <joint name="R_Middle2_y" type="hinge" pos="0 0 0" axis="0 1 0" user="100 10 1 150" armature="0.01" range="-180.0000 180.0000" damping="0" stiffness="0"/>
                        <joint name="R_Middle2_z" type="hinge" pos="0 0 0" axis="0 0 1" user="100 10 1 150" armature="0.01" range="-180.0000 180.0000" damping="0" stiffness="0"/>
                        <geom type="capsule" contype="1" conaffinity="1" density="1000" fromto="-0.0047 -0.0004 -0.0008 -0.0189 -0.0016 -0.0034" size="0.0072" name="R_Middle2"/>
                        <body name="R_Middle3" pos="-0.0237 -0.0021 -0.0042">
                          <joint name="R_Middle3_x" type="hinge" pos="0 0 0" axis="1 0 0" user="100 10 1 150" armature="0.01" range="-180.0000 180.0000" damping="0" stiffness="0"/>
                          <joint name="R_Middle3_y" type="hinge" pos="0 0 0" axis="0 1 0" user="100 10 1 150" armature="0.01" range="-180.0000 180.0000" damping="0" stiffness="0"/>
                          <joint name="R_Middle3_z" type="hinge" pos="0 0 0" axis="0 0 1" user="100 10 1 150" armature="0.01" range="-180.0000 180.0000" damping="0" stiffness="0"/>
                          <geom type="capsule" contype="1" conaffinity="1" density="1000" fromto="-0.0043 -0.0000 -0.0004 -0.0173 -0.0000 -0.0018" size="0.0065" name="R_Middle3"/>
                        </body>
                      </body>
                    </body>
                    <body name="R_Pinky1" pos="-0.0836 -0.0179 -0.0448">
                      <joint name="R_Pinky1_x" type="hinge" pos="0 0 0" axis="1 0 0" user="100 10 1 150" armature="0.01" range="-180.0000 180.0000" damping="0" stiffness="0"/>
                      <joint name="R_Pinky1_y" type="hinge" pos="0 0 0" axis="0 1 0" user="100 10 1 150" armature="0.01" range="-180.0000 180.0000" damping="0" stiffness="0"/>
                      <joint name="R_Pinky1_z" type="hinge" pos="0 0 0" axis="0 0 1" user="100 10 1 150" armature="0.01" range="-180.0000 180.0000" damping="0" stiffness="0"/>
                      <geom type="capsule" contype="1" conaffinity="1" density="1000" fromto="-0.0032 -0.0002 -0.0024 -0.0127 -0.0010 -0.0096" size="0.0069" name="R_Pinky1"/>
                      <body name="R_Pinky2" pos="-0.0159 -0.0012 -0.012">
                        <joint name="R_Pinky2_x" type="hinge" pos="0 0 0" axis="1 0 0" user="100 10 1 150" armature="0.01" range="-180.0000 180.0000" damping="0" stiffness="0"/>
                        <joint name="R_Pinky2_y" type="hinge" pos="0 0 0" axis="0 1 0" user="100 10 1 150" armature="0.01" range="-180.0000 180.0000" damping="0" stiffness="0"/>
                        <joint name="R_Pinky2_z" type="hinge" pos="0 0 0" axis="0 0 1" user="100 10 1 150" armature="0.01" range="-180.0000 180.0000" damping="0" stiffness="0"/>
                        <geom type="capsule" contype="1" conaffinity="1" density="1000" fromto="-0.0032 -0.0004 -0.0022 -0.0126 -0.0014 -0.0089" size="0.0067" name="R_Pinky2"/>
                        <body name="R_Pinky3" pos="-0.0158 -0.0018 -0.0112">
                          <joint name="R_Pinky3_x" type="hinge" pos="0 0 0" axis="1 0 0" user="100 10 1 150" armature="0.01" range="-180.0000 180.0000" damping="0" stiffness="0"/>
                          <joint name="R_Pinky3_y" type="hinge" pos="0 0 0" axis="0 1 0" user="100 10 1 150" armature="0.01" range="-180.0000 180.0000" damping="0" stiffness="0"/>
                          <joint name="R_Pinky3_z" type="hinge" pos="0 0 0" axis="0 0 1" user="100 10 1 150" armature="0.01" range="-180.0000 180.0000" damping="0" stiffness="0"/>
                          <geom type="capsule" contype="1" conaffinity="1" density="1000" fromto="-0.0028 0.0000 -0.0018 -0.0110 0.0002 -0.0073" size="0.0053" name="R_Pinky3"/>
                        </body>
                      </body>
                    </body>
                    <body name="R_Ring1" pos="-0.0972 -0.0123 -0.028">
                      <joint name="R_Ring1_x" type="hinge" pos="0 0 0" axis="1 0 0" user="100 10 1 150" armature="0.01" range="-180.0000 180.0000" damping="0" stiffness="0"/>
                      <joint name="R_Ring1_y" type="hinge" pos="0 0 0" axis="0 1 0" user="100 10 1 150" armature="0.01" range="-180.0000 180.0000" damping="0" stiffness="0"/>
                      <joint name="R_Ring1_z" type="hinge" pos="0 0 0" axis="0 0 1" user="100 10 1 150" armature="0.01" range="-180.0000 180.0000" damping="0" stiffness="0"/>
                      <geom type="capsule" contype="1" conaffinity="1" density="1000" fromto="-0.0057 0.0003 -0.0011 -0.0228 0.0012 -0.0042" size="0.0082" name="R_Ring1"/>
                      <body name="R_Ring2" pos="-0.0285 0.0015 -0.0053">
                        <joint name="R_Ring2_x" type="hinge" pos="0 0 0" axis="1 0 0" user="100 10 1 150" armature="0.01" range="-180.0000 180.0000" damping="0" stiffness="0"/>
                        <joint name="R_Ring2_y" type="hinge" pos="0 0 0" axis="0 1 0" user="100 10 1 150" armature="0.01" range="-180.0000 180.0000" damping="0" stiffness="0"/>
                        <joint name="R_Ring2_z" type="hinge" pos="0 0 0" axis="0 0 1" user="100 10 1 150" armature="0.01" range="-180.0000 180.0000" damping="0" stiffness="0"/>
                        <geom type="capsule" contype="1" conaffinity="1" density="1000" fromto="-0.0046 -0.0003 -0.0014 -0.0185 -0.0012 -0.0058" size="0.0076" name="R_Ring2"/>
                        <body name="R_Ring3" pos="-0.0231 -0.0016 -0.0072">
                          <joint name="R_Ring3_x" type="hinge" pos="0 0 0" axis="1 0 0" user="100 10 1 150" armature="0.01" range="-180.0000 180.0000" damping="0" stiffness="0"/>
                          <joint name="R_Ring3_y" type="hinge" pos="0 0 0" axis="0 1 0" user="100 10 1 150" armature="0.01" range="-180.0000 180.0000" damping="0" stiffness="0"/>
                          <joint name="R_Ring3_z" type="hinge" pos="0 0 0" axis="0 0 1" user="100 10 1 150" armature="0.01" range="-180.0000 180.0000" damping="0" stiffness="0"/>
                          <geom type="capsule" contype="1" conaffinity="1" density="1000" fromto="-0.0042 0.0001 -0.0010 -0.0169 0.0004 -0.0042" size="0.0061" name="R_Ring3"/>
                        </body>
                      </body>
                    </body>
                    <body name="R_Thumb1" pos="-0.0391 -0.0219 0.0263">
                      <joint name="R_Thumb1_x" type="hinge" pos="0 0 0" axis="1 0 0" user="100 10 1 150" armature="0.01" range="-180.0000 180.0000" damping="0" stiffness="0"/>
                      <joint name="R_Thumb1_y" type="hinge" pos="0 0 0" axis="0 1 0" user="100 10 1 150" armature="0.01" range="-180.0000 180.0000" damping="0" stiffness="0"/>
                      <joint name="R_Thumb1_z" type="hinge" pos="0 0 0" axis="0 0 1" user="100 10 1 150" armature="0.01" range="-180.0000 180.0000" damping="0" stiffness="0"/>
                      <geom type="capsule" contype="1" conaffinity="1" density="1000" fromto="-0.0034 0.0003 0.0050 -0.0138 0.0010 0.0202" size="0.0125" name="R_Thumb1"/>
                      <body name="R_Thumb2" pos="-0.0172 0.0013 0.0252">
                        <joint name="R_Thumb2_x" type="hinge" pos="0 0 0" axis="1 0 0" user="100 10 1 150" armature="0.01" range="-180.0000 180.0000" damping="0" stiffness="0"/>
                        <joint name="R_Thumb2_y" type="hinge" pos="0 0 0" axis="0 1 0" user="100 10 1 150" armature="0.01" range="-180.0000 180.0000" damping="0" stiffness="0"/>
                        <joint name="R_Thumb2_z" type="hinge" pos="0 0 0" axis="0 0 1" user="100 10 1 150" armature="0.01" range="-180.0000 180.0000" damping="0" stiffness="0"/>
                        <geom type="capsule" contype="1" conaffinity="1" density="1000" fromto="-0.0042 -0.0010 0.0031 -0.0167 -0.0042 0.0123" size="0.0098" name="R_Thumb2"/>
                        <body name="R_Thumb3" pos="-0.0209 -0.0052 0.0154">
                          <joint name="R_Thumb3_x" type="hinge" pos="0 0 0" axis="1 0 0" user="100 10 1 150" armature="0.01" range="-180.0000 180.0000" damping="0" stiffness="0"/>
                          <joint name="R_Thumb3_y" type="hinge" pos="0 0 0" axis="0 1 0" user="100 10 1 150" armature="0.01" range="-180.0000 180.0000" damping="0" stiffness="0"/>
                          <joint name="R_Thumb3_z" type="hinge" pos="0 0 0" axis="0 0 1" user="100 10 1 150" armature="0.01" range="-180.0000 180.0000" damping="0" stiffness="0"/>
                          <geom type="capsule" contype="1" conaffinity="1" density="1000" fromto="-0.0038 -0.0006 0.0035 -0.0151 -0.0026 0.0139" size="0.0092" name="R_Thumb3"/>
                        </body>
                      </body>
                    </body>
                  </body>
                </body>
              </body>
            </body>
          </body>
        </body>
      </body>
    </body>
  </worldbody>
  <actuator>
    <motor name="L_Hip_x" joint="L_Hip_x" gear="1"/>
    <motor name="L_Hip_y" joint="L_Hip_y" gear="1"/>
    <motor name="L_Hip_z" joint="L_Hip_z" gear="1"/>
    <motor name="L_Knee_x" joint="L_Knee_x" gear="1"/>
    <motor name="L_Knee_y" joint="L_Knee_y" gear="1"/>
    <motor name="L_Knee_z" joint="L_Knee_z" gear="1"/>
    <motor name="L_Ankle_x" joint="L_Ankle_x" gear="1"/>
    <motor name="L_Ankle_y" joint="L_Ankle_y" gear="1"/>
    <motor name="L_Ankle_z" joint="L_Ankle_z" gear="1"/>
    <motor name="L_Toe_x" joint="L_Toe_x" gear="1"/>
    <motor name="L_Toe_y" joint="L_Toe_y" gear="1"/>
    <motor name="L_Toe_z" joint="L_Toe_z" gear="1"/>
    <motor name="R_Hip_x" joint="R_Hip_x" gear="1"/>
    <motor name="R_Hip_y" joint="R_Hip_y" gear="1"/>
    <motor name="R_Hip_z" joint="R_Hip_z" gear="1"/>
    <motor name="R_Knee_x" joint="R_Knee_x" gear="1"/>
    <motor name="R_Knee_y" joint="R_Knee_y" gear="1"/>
    <motor name="R_Knee_z" joint="R_Knee_z" gear="1"/>
    <motor name="R_Ankle_x" joint="R_Ankle_x" gear="1"/>
    <motor name="R_Ankle_y" joint="R_Ankle_y" gear="1"/>
    <motor name="R_Ankle_z" joint="R_Ankle_z" gear="1"/>
    <motor name="R_Toe_x" joint="R_Toe_x" gear="1"/>
    <motor name="R_Toe_y" joint="R_Toe_y" gear="1"/>
    <motor name="R_Toe_z" joint="R_Toe_z" gear="1"/>
    <motor name="Torso_x" joint="Torso_x" gear="1"/>
    <motor name="Torso_y" joint="Torso_y" gear="1"/>
    <motor name="Torso_z" joint="Torso_z" gear="1"/>
    <motor name="Spine_x" joint="Spine_x" gear="1"/>
    <motor name="Spine_y" joint="Spine_y" gear="1"/>
    <motor name="Spine_z" joint="Spine_z" gear="1"/>
    <motor name="Chest_x" joint="Chest_x" gear="1"/>
    <motor name="Chest_y" joint="Chest_y" gear="1"/>
    <motor name="Chest_z" joint="Chest_z" gear="1"/>
    <motor name="Neck_x" joint="Neck_x" gear="1"/>
    <motor name="Neck_y" joint="Neck_y" gear="1"/>
    <motor name="Neck_z" joint="Neck_z" gear="1"/>
    <motor name="Head_x" joint="Head_x" gear="1"/>
    <motor name="Head_y" joint="Head_y" gear="1"/>
    <motor name="Head_z" joint="Head_z" gear="1"/>
    <motor name="L_Thorax_x" joint="L_Thorax_x" gear="1"/>
    <motor name="L_Thorax_y" joint="L_Thorax_y" gear="1"/>
    <motor name="L_Thorax_z" joint="L_Thorax_z" gear="1"/>
    <motor name="L_Shoulder_x" joint="L_Shoulder_x" gear="1"/>
    <motor name="L_Shoulder_y" joint="L_Shoulder_y" gear="1"/>
    <motor name="L_Shoulder_z" joint="L_Shoulder_z" gear="1"/>
    <motor name="L_Elbow_x" joint="L_Elbow_x" gear="1"/>
    <motor name="L_Elbow_y" joint="L_Elbow_y" gear="1"/>
    <motor name="L_Elbow_z" joint="L_Elbow_z" gear="1"/>
    <motor name="L_Wrist_x" joint="L_Wrist_x" gear="1"/>
    <motor name="L_Wrist_y" joint="L_Wrist_y" gear="1"/>
    <motor name="L_Wrist_z" joint="L_Wrist_z" gear="1"/>
    <motor name="L_Index1_x" joint="L_Index1_x" gear="1"/>
    <motor name="L_Index1_y" joint="L_Index1_y" gear="1"/>
    <motor name="L_Index1_z" joint="L_Index1_z" gear="1"/>
    <motor name="L_Index2_x" joint="L_Index2_x" gear="1"/>
    <motor name="L_Index2_y" joint="L_Index2_y" gear="1"/>
    <motor name="L_Index2_z" joint="L_Index2_z" gear="1"/>
    <motor name="L_Index3_x" joint="L_Index3_x" gear="1"/>
    <motor name="L_Index3_y" joint="L_Index3_y" gear="1"/>
    <motor name="L_Index3_z" joint="L_Index3_z" gear="1"/>
    <motor name="L_Middle1_x" joint="L_Middle1_x" gear="1"/>
    <motor name="L_Middle1_y" joint="L_Middle1_y" gear="1"/>
    <motor name="L_Middle1_z" joint="L_Middle1_z" gear="1"/>
    <motor name="L_Middle2_x" joint="L_Middle2_x" gear="1"/>
    <motor name="L_Middle2_y" joint="L_Middle2_y" gear="1"/>
    <motor name="L_Middle2_z" joint="L_Middle2_z" gear="1"/>
    <motor name="L_Middle3_x" joint="L_Middle3_x" gear="1"/>
    <motor name="L_Middle3_y" joint="L_Middle3_y" gear="1"/>
    <motor name="L_Middle3_z" joint="L_Middle3_z" gear="1"/>
    <motor name="L_Pinky1_x" joint="L_Pinky1_x" gear="1"/>
    <motor name="L_Pinky1_y" joint="L_Pinky1_y" gear="1"/>
    <motor name="L_Pinky1_z" joint="L_Pinky1_z" gear="1"/>
    <motor name="L_Pinky2_x" joint="L_Pinky2_x" gear="1"/>
    <motor name="L_Pinky2_y" joint="L_Pinky2_y" gear="1"/>
    <motor name="L_Pinky2_z" joint="L_Pinky2_z" gear="1"/>
    <motor name="L_Pinky3_x" joint="L_Pinky3_x" gear="1"/>
    <motor name="L_Pinky3_y" joint="L_Pinky3_y" gear="1"/>
    <motor name="L_Pinky3_z" joint="L_Pinky3_z" gear="1"/>
    <motor name="L_Ring1_x" joint="L_Ring1_x" gear="1"/>
    <motor name="L_Ring1_y" joint="L_Ring1_y" gear="1"/>
    <motor name="L_Ring1_z" joint="L_Ring1_z" gear="1"/>
    <motor name="L_Ring2_x" joint="L_Ring2_x" gear="1"/>
    <motor name="L_Ring2_y" joint="L_Ring2_y" gear="1"/>
    <motor name="L_Ring2_z" joint="L_Ring2_z" gear="1"/>
    <motor name="L_Ring3_x" joint="L_Ring3_x" gear="1"/>
    <motor name="L_Ring3_y" joint="L_Ring3_y" gear="1"/>
    <motor name="L_Ring3_z" joint="L_Ring3_z" gear="1"/>
    <motor name="L_Thumb1_x" joint="L_Thumb1_x" gear="1"/>
    <motor name="L_Thumb1_y" joint="L_Thumb1_y" gear="1"/>
    <motor name="L_Thumb1_z" joint="L_Thumb1_z" gear="1"/>
    <motor name="L_Thumb2_x" joint="L_Thumb2_x" gear="1"/>
    <motor name="L_Thumb2_y" joint="L_Thumb2_y" gear="1"/>
    <motor name="L_Thumb2_z" joint="L_Thumb2_z" gear="1"/>
    <motor name="L_Thumb3_x" joint="L_Thumb3_x" gear="1"/>
    <motor name="L_Thumb3_y" joint="L_Thumb3_y" gear="1"/>
    <motor name="L_Thumb3_z" joint="L_Thumb3_z" gear="1"/>
    <motor name="R_Thorax_x" joint="R_Thorax_x" gear="1"/>
    <motor name="R_Thorax_y" joint="R_Thorax_y" gear="1"/>
    <motor name="R_Thorax_z" joint="R_Thorax_z" gear="1"/>
    <motor name="R_Shoulder_x" joint="R_Shoulder_x" gear="1"/>
    <motor name="R_Shoulder_y" joint="R_Shoulder_y" gear="1"/>
    <motor name="R_Shoulder_z" joint="R_Shoulder_z" gear="1"/>
    <motor name="R_Elbow_x" joint="R_Elbow_x" gear="1"/>
    <motor name="R_Elbow_y" joint="R_Elbow_y" gear="1"/>
    <motor name="R_Elbow_z" joint="R_Elbow_z" gear="1"/>
    <motor name="R_Wrist_x" joint="R_Wrist_x" gear="1"/>
    <motor name="R_Wrist_y" joint="R_Wrist_y" gear="1"/>
    <motor name="R_Wrist_z" joint="R_Wrist_z" gear="1"/>
    <motor name="R_Index1_x" joint="R_Index1_x" gear="1"/>
    <motor name="R_Index1_y" joint="R_Index1_y" gear="1"/>
    <motor name="R_Index1_z" joint="R_Index1_z" gear="1"/>
    <motor name="R_Index2_x" joint="R_Index2_x" gear="1"/>
    <motor name="R_Index2_y" joint="R_Index2_y" gear="1"/>
    <motor name="R_Index2_z" joint="R_Index2_z" gear="1"/>
    <motor name="R_Index3_x" joint="R_Index3_x" gear="1"/>
    <motor name="R_Index3_y" joint="R_Index3_y" gear="1"/>
    <motor name="R_Index3_z" joint="R_Index3_z" gear="1"/>
    <motor name="R_Middle1_x" joint="R_Middle1_x" gear="1"/>
    <motor name="R_Middle1_y" joint="R_Middle1_y" gear="1"/>
    <motor name="R_Middle1_z" joint="R_Middle1_z" gear="1"/>
    <motor name="R_Middle2_x" joint="R_Middle2_x" gear="1"/>
    <motor name="R_Middle2_y" joint="R_Middle2_y" gear="1"/>
    <motor name="R_Middle2_z" joint="R_Middle2_z" gear="1"/>
    <motor name="R_Middle3_x" joint="R_Middle3_x" gear="1"/>
    <motor name="R_Middle3_y" joint="R_Middle3_y" gear="1"/>
    <motor name="R_Middle3_z" joint="R_Middle3_z" gear="1"/>
    <motor name="R_Pinky1_x" joint="R_Pinky1_x" gear="1"/>
    <motor name="R_Pinky1_y" joint="R_Pinky1_y" gear="1"/>
    <motor name="R_Pinky1_z" joint="R_Pinky1_z" gear="1"/>
    <motor name="R_Pinky2_x" joint="R_Pinky2_x" gear="1"/>
    <motor name="R_Pinky2_y" joint="R_Pinky2_y" gear="1"/>
    <motor name="R_Pinky2_z" joint="R_Pinky2_z" gear="1"/>
    <motor name="R_Pinky3_x" joint="R_Pinky3_x" gear="1"/>
    <motor name="R_Pinky3_y" joint="R_Pinky3_y" gear="1"/>
    <motor name="R_Pinky3_z" joint="R_Pinky3_z" gear="1"/>
    <motor name="R_Ring1_x" joint="R_Ring1_x" gear="1"/>
    <motor name="R_Ring1_y" joint="R_Ring1_y" gear="1"/>
    <motor name="R_Ring1_z" joint="R_Ring1_z" gear="1"/>
    <motor name="R_Ring2_x" joint="R_Ring2_x" gear="1"/>
    <motor name="R_Ring2_y" joint="R_Ring2_y" gear="1"/>
    <motor name="R_Ring2_z" joint="R_Ring2_z" gear="1"/>
    <motor name="R_Ring3_x" joint="R_Ring3_x" gear="1"/>
    <motor name="R_Ring3_y" joint="R_Ring3_y" gear="1"/>
    <motor name="R_Ring3_z" joint="R_Ring3_z" gear="1"/>
    <motor name="R_Thumb1_x" joint="R_Thumb1_x" gear="1"/>
    <motor name="R_Thumb1_y" joint="R_Thumb1_y" gear="1"/>
    <motor name="R_Thumb1_z" joint="R_Thumb1_z" gear="1"/>
    <motor name="R_Thumb2_x" joint="R_Thumb2_x" gear="1"/>
    <motor name="R_Thumb2_y" joint="R_Thumb2_y" gear="1"/>
    <motor name="R_Thumb2_z" joint="R_Thumb2_z" gear="1"/>
    <motor name="R_Thumb3_x" joint="R_Thumb3_x" gear="1"/>
    <motor name="R_Thumb3_y" joint="R_Thumb3_y" gear="1"/>
    <motor name="R_Thumb3_z" joint="R_Thumb3_z" gear="1"/>
  </actuator>
  <contact>
    <exclude body1="Torso" body2="Chest"/>
    <exclude body1="Head" body2="Chest"/>
    <exclude body1="R_Knee" body2="R_Toe"/>
    <exclude body1="R_Knee" body2="L_Ankle"/>
    <exclude body1="R_Knee" body2="L_Toe"/>
    <exclude body1="L_Knee" body2="L_Toe"/>
    <exclude body1="L_Knee" body2="R_Ankle"/>
    <exclude body1="L_Knee" body2="R_Toe"/>
    <exclude body1="L_Shoulder" body2="Chest"/>
    <exclude body1="R_Shoulder" body2="Chest"/>
  </contact>
  <sensor/>
  <size njmax="700" nconmax="700"/>
</mujoco>
